// Sample program to show how wrapping errors work with the stdlib.
package main

import (
	"errors"
	"fmt"
)

// AppError represents a custom error type.
type AppError struct {
	State int
}

// Error implements the error interface.
func (c *AppError) Error() string {
	return fmt.Sprintf("App Error, State: %d", c.State)
}

func main() {

	// Make the function call and validate the error.
	if err := firstCall(10); err != nil {

		// Use type as context to determine cause.
		switch v := errors.Unwrap(err).(type) {
		case *AppError:

			// We got our custom error type.
			fmt.Println("Custom App Error:", v.State)

		default:

			// We did not get any specific error type.
			fmt.Println("Default Error")
		}

		// Display the error.
		fmt.Println("\n********************************")
		fmt.Printf("%v\n", err)
	}
}

// firstCall makes a call to a second function and wraps any error.
func firstCall(i int) error {
	if err := secondCall(i); err != nil {
		return fmt.Errorf("firstCall->secondCall(%d) : %w", i, err)
	}
	return nil
}

// secondCall makes a call to a third function and wraps any error.
func secondCall(i int) error {
	if err := thirdCall(); err != nil {
		return fmt.Errorf("secondCall->thirdCall() : %w", err)
	}
	return nil
}

// thirdCall create an error value we will validate.
func thirdCall() error {
	return &AppError{99}
}
